Workbook

Sheet 分段分析
B3: brsw: 1680
C5: N | D5: H | E5: W | F5: spc_num | G5: seq_idx | H5: 优化前ms | I5: 优化后ms | J5: 收益 | L5: 除去最后reorder | M5: 去掉score*value和reorder | N5: 去掉Q*KT和softmax | O5: Q*KT | P5: 只有softmax | Q5: softmax前半部分 | R5: softmax后半部分 | U5: flash attention | V5: 除去最后reorder | W5: 去掉score*value和reorder | X5: 去除mma reorder，只有关于softmax的计算 | AB5: 优化前ms | AC5: 优化后ms
B6: decoder | C6: 1 | D6: 1 | E6: 2048 | F6: 16 | G6: 1 | H6: 0.031123 | I6: 0.036768 | J6: =(H6-I6)/H6 -> -0.18137712 | L6: 0.031917ms. | M6: 0.021933ms. | N6: 0.025286ms. | O6: 0.024634ms. | P6: 0.019994ms. | Q6: 0.018861ms. | R6: 0.024896ms. | U6: 0.030899ms. | V6: 0.029075ms. | W6: 0.024538ms. | X6: 0.018394ms. | Z6: 0.018362ms. | AB6: 0.031123 | AC6: 0.036768 | AE6: 0.033094ms. | AG6: 0.032621ms.
C7: 1 | D7: 1 | E7: 2048 | F7: 16 | G7: 127 | H7: 0.032736 | I7: 0.040531 | J7: =(H7-I7)/H7 -> -0.23811706 | L7: 0.034739ms. | M7: 0.023757ms. | N7: 0.024730ms. | O7: 0.025094ms. | P7: 0.020346ms. | Q7: 0.024205ms. | R7: 0.025766ms. | U7: 0.041555ms. | V7: 0.027450ms. | W7: 0.025056ms. | X7: 0.018054ms. | Z7: 0.018010ms. | AB7: 0.032736 | AC7: 0.040531 | AE7: 0.033702ms. | AG7: 0.033715ms.
C8: 1 | D8: 1 | E8: 2048 | F8: 16 | G8: 511 | H8: 0.05449 | I8: 0.062605 | J8: =(H8-I8)/H8 -> -0.14892641 | L8: 0.057088ms. | M8: 0.046086ms. | N8: 0.101830ms. | O8: 0.024979ms. | P8: 0.025645ms. | Q8: 0.018298ms. | R8: 0.030938ms. | U8: 0.072653ms. | V8: 0.066163ms. | W8: 0.051008ms. | X8: 0.023872ms. | Z8: 0.018003ms. | AB8: 0.05449 | AC8: 0.062605 | AE8: 0.056730ms. | AG8: 0.056314ms.
C9: 1 | D9: 1 | E9: 2048 | F9: 16 | G9: 1023 | H9: 0.081914 | I9: 0.091162 | J9: =(H9-I9)/H9 -> -0.11289889 | L9: 0.085254ms. | M9: 0.067443ms. | N9: 0.047891ms. | O9: 0.040154ms. | P9: 0.037766ms. | Q9: 0.026918ms. | R9: 0.037619ms. | U9: 0.107078ms. | V9: 0.099206ms. | W9: 0.073146ms. | X9: 0.030682ms. | Z9: 0.020294ms. | AB9: 0.081914 | AC9: 0.091162 | AE9: 0.088416ms. | AG9: 0.086266ms.
C10: 1 | D10: 1 | E10: 2048 | F10: 16 | G10: 2047 | H10: 0.136762 | I10: 0.14464 | J10: =(H10-I10)/H10 -> -0.05760372 | L10: 0.137907ms. | M10: 0.102906ms. | N10: 0.065786ms. | O10: 0.054432ms. | P10: 0.057254ms. | Q10: 0.030368ms. | R10: 0.084787ms. | U10: 0.171789ms. | V10: 0.164333ms. | W10: 0.117254ms. | X10: 0.044122ms. | Z10: 0.023603ms. | AB10: 0.136762 | AC10: 0.14464 | AE10: 0.138163ms. | AG10: 0.133856ms.
C11: 1 | D11: 1 | E11: 2048 | F11: 16 | G11: 4095 | H11: 0.24784 | I11: 0.253338 | J11: =(H11-I11)/H11 -> -0.022183667 | L11: 0.245056ms. | M11: 0.174470ms. | N11: 0.165638ms. | O11: 0.082624ms. | P11: 0.095981ms. | Q11: 0.030310ms. | R11: 0.079398ms. | U11: 0.295789ms. | V11: 0.289056ms. | W11: 0.205184ms. | X11: 0.070995ms. | Z11: 0.030208ms. | AB11: 0.24784 | AC11: 0.253338 | AE11: 0.239514ms. | AG11: 0.229197ms.
C12: 4 | D12: 1 | E12: 2048 | F12: 16 | G12: 1 | H12: 0.059059 | I12: 0.059386 | J12: =(H12-I12)/H12 -> -0.005536836 | L12: 0.053203ms. | M12: 0.039565ms. | N12: 0.040499ms. | O12: 0.026458ms. | P12: 0.033702ms. | Q12: 0.018848ms. | R12: 0.031181ms. | U12: 0.056326ms. | V12: 0.046714ms. | W12: 0.027258ms. | X12: 0.026720ms. | Z12: 0.025574ms. | AB12: 0.059059 | AC12: 0.059386 | AE12: 0.064013ms. | AG12: 0.063584ms.
C13: 4 | D13: 1 | E13: 2048 | F13: 16 | G13: 127 | H13: 0.068819 | I13: 0.068307 | J13: =(H13-I13)/H13 -> 0.0074398059 | L13: 0.062342ms. | M13: 0.048493ms. | N13: 0.040256ms. | O13: 0.026701ms. | P13: 0.037114ms. | Q13: 0.018829ms. | R13: 0.034458ms. | U13: 0.073242ms. | V13: 0.064224ms. | W13: 0.027174ms. | X13: 0.026554ms. | Z13: 0.025773ms. | AB13: 0.068819 | AC13: 0.068307 | AE13: 0.068557ms. | AG13: 0.068781ms.
C14: 4 | D14: 1 | E14: 2048 | F14: 16 | G14: 511 | H14: 0.148 | I14: 0.150886 | J14: =(H14-I14)/H14 -> -0.0195 | L14: 0.142854ms. | M14: 0.109894ms. | N14: 0.068141ms. | O14: 0.026650ms. | P14: 0.058067ms. | Q14: 0.025114ms. | R14: 0.055290ms. | U14: 0.182541ms. | V14: 0.173114ms. | W14: 0.121107ms. | X14: 0.053312ms. | Z14: 0.025741ms. | AB14: 0.148 | AC14: 0.150886 | AE14: 0.147962ms. | AG14: 0.149152ms.
C15: 4 | D15: 1 | E15: 2048 | F15: 16 | G15: 1022 | H15: 0.265587 | I15: 0.272077 | J15: =(H15-I15)/H15 -> -0.024436437 | L15: 0.257728ms. | M15: 0.194586ms. | N15: 0.106490ms. | O15: 0.026566ms. | P15: 0.091008ms. | Q15: 0.018771ms. | R15: 0.082611ms. | U15: 0.336070ms. | V15: 0.328269ms. | W15: 0.120640ms. | X15: 0.053274ms. | Z15: 0.025850ms. | AB15: 0.265587 | AC15: 0.272077 | AE15: 0.264109ms. | AG15: 0.263302ms.
C16: 4 | D16: 1 | E16: 2048 | F16: 16 | G16: 2047 | H16: 0.492288 | I16: 0.48704 | J16: =(H16-I16)/H16 -> 0.010660426 | L16: 0.482682ms. | M16: 0.347264ms. | N16: 0.181792ms. | O16: 0.145197ms. | P16: 0.184525ms. | Q16: 0.045638ms. | R16: 0.145062ms. | U16: 0.548390ms. | V16: 0.538413ms. | W16: 0.381702ms. | X16: 0.133843ms. | Z16: 0.052506ms. | AB16: 0.492288 | AC16: 0.48704 | AE16: 0.473696ms. | AG16: 0.456736ms.
C17: 4 | D17: 1 | E17: 2048 | F17: 16 | G17: 4095 | H17: 0.942573 | I17: 0.922387 | J17: =(H17-I17)/H17 -> 0.021415848 | L17: 0.915962ms. | M17: 0.649466ms. | N17: 0.522835ms. | O17: 0.257197ms. | P17: 0.339648ms. | Q17: 0.072134ms. | R17: 0.263526ms. | U17: 1.029197ms. | V17: 1.018982ms. | W17: 0.727930ms. | X17: 0.241894ms. | Z17: 0.079104ms. | AB17: 0.942573 | AC17: 0.922387 | AE17: 0.888128ms. | AG17: 0.847558ms.
C18: 8 | D18: 1 | E18: 2048 | F18: 16 | G18: 1 | H18: 0.085984 | I18: 0.086976 | J18: =(H18-I18)/H18 -> -0.01153703 | L18: 0.082067ms. | M18: 0.055546ms. | N18: 0.053498ms. | O18: 0.029587ms. | P18: 0.043571ms. | Q18: 0.027584ms. | R18: 0.038074ms. | U18: 0.082707ms. | V18: 0.069062ms. | W18: 0.030336ms. | X18: 0.029811ms. | Z18: 0.028154ms. | AB18: 0.085984 | AC18: 0.086976 | AE18: 0.095424ms. | AG18: 0.095846ms.
... C35: 20 | D35: 1 | E35: 2048 | F35: 16 | G35: 4095 | H35: 4.555181 | I35: 4.478893 | J35: =(H35-I35)/H35 -> 0.016747523 | L35: 4.453709ms. | M35: 3.055866ms. | N35: 1.520499ms. | O35: 1.177734ms. | P35: 1.958470ms. | Q35: 0.301133ms. | R35: 1.740570ms. | U35: 4.928282ms. | V35: 4.900038ms. | W35: 3.505472ms. | X35: 1.115213ms. | Z35: 0.301779ms. | AB35: 4.555181 | AC35: 4.478893 | AE35: 4.270522ms. | AG35: 4.092717ms.
B36: encoder | C36: 1 | D36: 1 | E36: 2048 | F36: 16 | G36: 0 | H36: 0.037542 | I36: 0.037619 | J36: =(H36-I36)/H36 -> -0.0020510362 | L36: 0.032282ms. | M36: 0.027859ms. | N36: 0.031398ms. | O36: 0.024774ms. | P36: 0.026554ms. | Q36: 0.024595ms. | R36: 0.025158ms. | U36: 0.037517ms. | V36: 0.022893ms. | W36: 0.024909ms. | X36: 0.025030ms. | Z36: 0.024954ms. | AB36: 0.037542 | AC36: 0.037619 | AE36: 0.039341ms. | AG36: 0.039194ms.
C37: 1 | D37: 128 | E37: 2048 | F37: 16 | G37: 0 | H37: 0.059846 | I37: 0.059514 | J37: =(H37-I37)/H37 -> 0.0055475721 | L37: 0.042208ms. | M37: 0.037811ms. | N37: 0.042874ms. | O37: 0.024851ms. | P37: 0.031328ms. | Q37: 0.024154ms. | R37: 0.029069ms. | U37: 0.071968ms. | V37: 0.044205ms. | W37: 0.024928ms. | X37: 0.025075ms. | Z37: 0.025082ms. | AB37: 0.059846 | AC37: 0.059514 | AE37: 0.060589ms. | AG37: 0.060410ms.
C38: 1 | D38: 512 | E38: 2048 | F38: 16 | G38: 0 | H38: 0.311866 | I38: 0.313293 | J38: =(H38-I38)/H38 -> -0.0045756831 | L38: 0.255238ms. | M38: 0.222061ms. | N38: 0.109990ms. | O38: 0.025805ms. | P38: 0.092186ms. | Q38: 0.024774ms. | R38: 0.083277ms. | U38: 0.455770ms. | V38: 0.361267ms. | W38: 0.256307ms. | X38: 0.102682ms. | Z38: 0.025101ms. | AB38: 0.311866 | AC38: 0.313293 | AE38: 0.305402ms. | AG38: 0.304634ms.
C39: 1 | D39: 1024 | E39: 2048 | F39: 16 | G39: 0 | H39: 1.37001 | I39: 1.286253 | J39: =(H39-I39)/H39 -> 0.06113605 | L39: 1.164186ms. | M39: 0.963898ms. | N39: 0.251840ms. | O39: 0.287085ms. | P39: 0.706938ms. | Q39: 0.243539ms. | R39: 0.465888ms. | U39: 1.540845ms. | V39: 1.347008ms. | W39: 0.963117ms. | X39: 0.351034ms. | Z39: 0.316205ms. | AB39: 1.37001 | AC39: 1.286253 | AE39: 1.258400ms. | AG39: 1.236493ms.
C40: 1 | D40: 2048 | E40: 2048 | F40: 16 | G40: 0 | H40: 5.157664 | I40: 4.953197 | J40: =(H40-I40)/H40 -> 0.039643335 | L40: 4.666547ms. | M40: 4.059770ms. | N40: 0.896339ms. | O40: 1.030464ms. | P40: 3.203181ms. | Q40: 1.254989ms. | R40: 1.807136ms. | U40: 5.599322ms. | V40: 5.198368ms. | W40: 3.908851ms. | X40: 1.543424ms. | Z40: 1.257555ms. | AB40: 5.157664 | AC40: 4.953197 | AE40: 4.770982ms. | AG40: 4.676480ms.
C41: 1 | D41: 4096 | E41: 2048 | F41: 16 | G41: 0 | H41: 19.437569 | I41: 19.061766 | J41: =(H41-I41)/H41 -> 0.019333848 | L41: 18.486540ms. | M41: 16.407988ms. | N41: 2.973773ms. | O41: 3.922137ms. | P41: 12.584890ms. | Q41: 5.054906ms. | R41: 6.864173ms. | U41: 21.169781ms. | V41: 20.177620ms. | W41: 14.518964ms. | X41: 7.014912ms. | Z41: 5.148980ms. | AB41: 19.437569 | AC41: 19.061766 | AE41: 18.079775ms. | AG41: 17.783495ms.
C42: 4 | D42: 1 | E42: 2048 | F42: 16 | G42: 0 | H42: 0.058298 | I42: 0.058861 | J42: =(H42-I42)/H42 -> -0.0096572781 | L42: 0.053446ms. | M42: 0.032896ms. | N42: 0.041082ms. | O42: 0.026496ms. | P42: 0.033862ms. | Q42: 0.025107ms. | R42: 0.030912ms. | U42: 0.056506ms. | V42: 0.046336ms. | W42: 0.027104ms. | X42: 0.026029ms. | Z42: 0.025498ms. | AB42: 0.058298 | AC42: 0.058861 | AE42: 0.063814ms. | AG42: 0.062362ms.
C43: 4 | D43: 128 | E43: 2048 | F43: 16 | G43: 0 | H43: 0.153907 | I43: 0.159763 | J43: =(H43-I43)/H43 -> -0.038048952 | L43: 0.096179ms. | M43: 0.081472ms. | N43: 0.089037ms. | O43: 0.027533ms. | P43: 0.053242ms. | Q43: 0.025670ms. | R43: 0.046995ms. | U43: 0.194214ms. | V43: 0.097811ms. | W43: 0.028045ms. | X43: 0.027616ms. | Z43: 0.025869ms. | AB43: 0.153907 | AC43: 0.159763 | AE43: 0.147603ms. | AG43: 0.149056ms.
C44: 4 | D44: 512 | E44: 2048 | F44: 16 | G44: 0 | H44: 1.412346 | I44: 1.34743 | J44: =(H44-I44)/H44 -> 0.045963241 | L44: 1.087296ms. | M44: 0.921030ms. | N44: 0.342432ms. | O44: 0.032870ms. | P44: 0.473747ms. | Q44: 0.027782ms. | R44: 0.461536ms. | U44: 1.714016ms. | V44: 1.344122ms. | W44: 0.952614ms. | X44: 0.351930ms. | Z44: 0.028282ms. | AB44: 1.412346 | AC44: 1.34743 | AE44: 1.290810ms. | AG44: 1.292730ms.
C45: 4 | D45: 1024 | E45: 2048 | F45: 16 | G45: 0 | H45: 5.662618 | I45: 5.388934 | J45: =(H45-I45)/H45 -> 0.048331708 | L45: 4.818643ms. | M45: 4.220409ms. | N45: 1.198298ms. | O45: 1.058355ms. | P45: 3.086912ms. | Q45: 1.384390ms. | R45: 1.738528ms. | U45: 6.367853ms. | V45: 5.322662ms. | W45: 3.847501ms. | X45: 1.408262ms. | Z45: 1.389082ms. | AB45: 5.662618 | AC45: 5.388934 | AE45: 5.312794ms. | AG45: 5.169024ms.
C46: 4 | D46: 2048 | E46: 2048 | F46: 16 | G46: 0 | H46: 20.983694 | I46: 20.394573 | J46: =(H46-I46)/H46 -> 0.028075181 | L46: 19.148134ms. | M46: 16.772448ms. | N46: 3.630887ms. | O46: 3.949293ms. | P46: 13.279226ms. | Q46: 5.583040ms. | R46: 6.786304ms. | U46: 24.088562ms. | V46: 21.579674ms. | W46: 15.461626ms. | X46: 7.366112ms. | Z46: 5.626048ms. | AB46: 20.983694 | AC46: 20.394573 | AE46: 20.119520ms. | AG46: 19.527054ms.
C47: 4 | D47: 4096 | E47: 2048 | F47: 16 | G47: 0 | H47: 80.462173 | I47: 79.3536 | J47: =(H47-I47)/H47 -> 0.013777567 | L47: 75.595406ms. | M47: 66.503952ms. | N47: 13.173266ms. | O47: 15.171636ms. | P47: 52.432949ms. | Q47: 22.689312ms. | R47: 26.255894ms. | U47: 90.212372ms. | V47: 86.015778ms. | W47: 62.874111ms. | X47: 29.642654ms. | Z47: 22.315418ms. | AB47: 80.462173 | AC47: 79.3536 | AE47: 76.858009ms. | AG47: 74.825989ms.
C48: 8 | D48: 1 | E48: 2048 | F48: 16 | G48: 0 | H48: 0.086291 | I48: 0.087334 | J48: =(H48-I48)/H48 -> -0.012087008 | L48: 0.081926ms. | M48: 0.055699ms. | N48: 0.053299ms. | O48: 0.029197ms. | P48: 0.043098ms. | Q48: 0.028090ms. | R48: 0.037619ms. | U48: 0.082227ms. | V48: 0.069165ms. | W48: 0.030246ms. | X48: 0.029914ms. | Z48: 0.027968ms. | AB48: 0.086291 | AC48: 0.087334 | AE48: 0.095610ms. | AG48: 0.095878ms.
... C53: 16 | D53: 1 | E53: 2048 | F53: 16 | G53: 0 | H53: 0.144704 | I53: 0.147706 | J53: =(H53-I53)/H53 -> -0.020745798 | L53: 0.140992ms. | M53: 0.088877ms. | N53: 0.081037ms. | O53: 0.035238ms. | P53: 0.068851ms. | Q53: 0.031360ms. | R53: 0.053139ms. | U53: 0.135322ms. | V53: 0.115398ms. | W53: 0.036230ms. | X53: 0.036019ms. | Z53: 0.032627ms. | AB53: 0.144704 | AC53: 0.147706 | AE53: 0.162426ms. | AG53: 0.161299ms.
C54: 16 | D54: 128 | E54: 2048 | F54: 16 | G54: 0 | H54: 0.61977 | I54: 0.595782 | J54: =(H54-I54)/H54 -> 0.038704681 | L54: 0.340595ms. | M54: 0.273216ms. | N54: 0.333293ms. | P54: 0.154592ms. | Q54: 0.034131ms. | R54: 0.143290ms. | U54: 0.694099ms. | V54: 0.340192ms. | W54: 0.040320ms. | X54: 0.043718ms. | Z54: 0.034368ms. | AB54: 0.61977 | AC54: 0.595782 | AE54: 0.582726ms. | AG54: 0.588083ms.
C55: 16 | D55: 512 | E55: 2048 | F55: 16 | G55: 0 | H55: 5.712858 | I55: 5.55127 | J55: =(H55-I55)/H55 -> 0.028284967 | L55: 4.256819ms. | M55: 3.671955ms. | N55: 1.842515ms. | P55: 1.765894ms. | Q55: 0.042656ms. | R55: 1.708723ms. | U55: 7.773837ms. | V55: 5.401971ms. | W55: 3.752346ms. | X55: 1.609818ms. | Z55: 0.042714ms. | AB55: 5.712858 | AC55: 5.55127 | AE55: 5.402893ms. | AG55: 5.375616ms.
C56: 20 | D56: 1 | E56: 2048 | F56: 16 | G56: 0 | H56: 0.173171 | I56: 0.177734 | J56: =(H56-I56)/H56 -> -0.026349677 | L56: 0.170336ms. | M56: 0.105331ms. | N56: 0.093709ms. | P56: 0.080563ms. | Q56: 0.035014ms. | R56: 0.094234ms. | U56: 0.162912ms. | V56: 0.138387ms. | W56: 0.039584ms. | X56: 0.039251ms. | Z56: 0.035315ms. | AB56: 0.173171 | AC56: 0.177734 | AE56: 0.193958ms. | AG56: 0.194182ms.
C57: 20 | D57: 128 | E57: 2048 | F57: 16 | G57: 0 | H57: 0.772102 | I57: 0.731213 | J57: =(H57-I57)/H57 -> 0.052958029 | L57: 0.420371ms. | M57: 0.338304ms. | N57: 0.765056ms. | P57: 0.188659ms. | Q57: 0.037011ms. | R57: 0.177056ms. | U57: 0.917434ms. | V57: 0.415558ms. | W57: 0.044358ms. | X57: 0.048922ms. | Z57: 0.037158ms. | AB57: 0.772102 | AC57: 0.731213 | AE57: 0.710720ms. | AG57: 0.723827ms.

Sheet softmax_pingpong
C4: N | D4: H | E4: W | F4: spc_num | G4: seq_idx | H4: 优化前ms | I4: 优化后ms | J4: 收益
C5: decoder | D5: 1 | E5: 1 | F5: 2048 | G5: 16 | H5: 1 | I5: 0.037318 | J5: 0.038726 | K5: -0.0377
D6: 1 | E6: 1 | F6: 2048 | G6: 16 | H6: 127 | I6: 0.039642 | J6: 0.041018 | K6: -0.0347
D7: 1 | E7: 1 | F7: 2048 | G7: 16 | H7: 511 | I7: 0.061466 | J7: 0.063872 | K7: -0.0391
D8: 1 | E8: 1 | F8: 2048 | G8: 16 | H8: 1023 | I8: 0.089248 | J8: 0.095462 | K8: -0.0696
D9: 1 | E9: 1 | F9: 2048 | G9: 16 | H9: 2047 | I9: 0.144064 | J9: 0.145792 | K9: -0.012
D10: 1 | E10: 1 | F10: 2048 | G10: 16 | H10: 4095 | I10: 0.25591 | J10: 0.245869 | K10: 0.0392
D11: 4 | E11: 1 | F11: 2048 | G11: 16 | H11: 1 | I11: 0.05975 | J11: 0.06199 | K11: -0.0375
D12: 4 | E12: 1 | F12: 2048 | G12: 16 | H12: 127 | I12: 0.070509 | J12: 0.07024 | K12: 0.0038
D13: 4 | E13: 1 | F13: 2048 | G13: 16 | H13: 511 | I13: 0.156909 | J13: 0.149894 | K13: 0.0447
D14: 4 | E14: 1 | F14: 2048 | G14: 16 | H14: 1022 | I14: 0.273632 | J14: 0.26071 | K14: 0.0472
D15: 4 | E15: 1 | F15: 2048 | G15: 16 | H15: 2047 | I15: 0.508154 | J15: 0.467712 | K15: 0.0796
D16: 4 | E16: 1 | F16: 2048 | G16: 16 | H16: 4095 | I16: 0.982176 | J16: 0.87952 | K16: 0.1045
D17: 8 | E17: 1 | F17: 2048 | G17: 16 | H17: 1 | I17: 0.089619 | J17: 0.094298 | K17: -0.0522
... D34: 20 | E34: 1 | F34: 2048 | G34: 16 | H34: 4095 | I34: 4.718733 | J34: 4.186022 | K34: 0.1129
C35: encoder | D35: 1 | E35: 1 | F35: 2048 | G35: 16 | H35: 0 | I35: 0.0376 | J35: 0.039072 | K35: -0.0391
D36: 1 | E36: 128 | F36: 2048 | G36: 16 | H36: 0 | I36: 0.060038 | J36: 0.060109 | K36: -0.0012
D37: 1 | E37: 512 | F37: 2048 | G37: 16 | H37: 0 | I37: 0.311674 | J37: 0.305875 | K37: 0.0186
D38: 1 | E38: 1024 | F38: 2048 | G38: 16 | H38: 0 | I38: 1.340755 | J38: 1.295181 | K38: 0.034
D39: 1 | E39: 2048 | F39: 2048 | G39: 16 | H39: 0 | I39: 5.057286 | J39: 4.805178 | K39: 0.0499
D40: 1 | E40: 4096 | F40: 2048 | G40: 16 | H40: 0 | I40: 18.93805 | J40: 18.1703 | K40: 0.0405
D41: 4 | E41: 1 | F41: 2048 | G41: 16 | H41: 0 | I41: 0.059827 | J41: 0.062522 | K41: -0.045
D42: 4 | E42: 128 | F42: 2048 | G42: 16 | H42: 0 | I42: 0.157453 | J42: 0.158842 | K42: -0.0088
D43: 4 | E43: 512 | F43: 2048 | G43: 16 | H43: 0 | I43: 1.43657 | J43: 1.31776 | K43: 0.0827
D44: 4 | E44: 1024 | F44: 2048 | G44: 16 | H44: 0 | I44: 5.679334 | J44: 5.327539 | K44: 0.0619
D45: 4 | E45: 2048 | F45: 2048 | G45: 16 | H45: 0 | I45: 21.20708 | J45: 20.02506 | K45: 0.0557
D46: 4 | E46: 4096 | F46: 2048 | G46: 16 | H46: 0 | I46: 79.60851 | J46: 77.03525 | K46: 0.0323
D47: 8 | E47: 1 | F47: 2048 | G47: 16 | H47: 0 | I47: 0.090355 | J47: 0.09385 | K47: -0.0387
... D56: 20 | E56: 128 | F56: 2048 | G56: 16 | H56: 0 | I56: 0.780704 | J56: 0.725811 | K56: 0.0703

Sheet NUMA_UMA
B3: brsw: 1680
H4: NUMA | I4: UMA
C5: N | D5: H | E5: W | F5: spc_num | G5: seq_idx | H5: 优化前ms | I5: 优化后ms | J5: 收益
B6: decoder | C6: 1 | D6: 1 | E6: 2048 | F6: 16 | G6: 1 | H6: 0.038726 | I6: 0.03655 | J6: =(H6-I6)/H6 -> 0.05618964
C7: 1 | D7: 1 | E7: 2048 | F7: 16 | G7: 127 | H7: 0.041018 | I7: 0.038637 | J7: =(H7-I7)/H7 -> 0.058047686
C8: 1 | D8: 1 | E8: 2048 | F8: 16 | G8: 511 | H8: 0.063872 | I8: 0.05497 | J8: =(H8-I8)/H8 -> 0.13937249
C9: 1 | D9: 1 | E9: 2048 | F9: 16 | G9: 1023 | H9: 0.095462 | I9: 0.072621 | J9: =(H9-I9)/H9 -> 0.23926798
C10: 1 | D10: 1 | E10: 2048 | F10: 16 | G10: 2047 | H10: 0.145792 | I10: 0.110067 | J10: =(H10-I10)/H10 -> 0.24504088
C11: 1 | D11: 1 | E11: 2048 | F11: 16 | G11: 4095 | H11: 0.245869 | I11: 0.187853 | J11: =(H11-I11)/H11 -> 0.23596305
C12: 4 | D12: 1 | E12: 2048 | F12: 16 | G12: 1 | H12: 0.06199 | I12: 0.057766 | J12: =(H12-I12)/H12 -> 0.068140023
C13: 4 | D13: 1 | E13: 2048 | F13: 16 | G13: 127 | H13: 0.07024 | I13: 0.066054 | J13: =(H13-I13)/H13 -> 0.059595672
C14: 4 | D14: 1 | E14: 2048 | F14: 16 | G14: 511 | H14: 0.149894 | I14: 0.134246 | J14: =(H14-I14)/H14 -> 0.10439377
C15: 4 | D15: 1 | E15: 2048 | F15: 16 | G15: 1022 | H15: 0.26071 | I15: 0.220333 | J15: =(H15-I15)/H15 -> 0.15487323
C16: 4 | D16: 1 | E16: 2048 | F16: 16 | G16: 2047 | H16: 0.467712 | I16: 0.38807 | J16: =(H16-I16)/H16 -> 0.17028
C17: 4 | D17: 1 | E17: 2048 | F17: 16 | G17: 4095 | H17: 0.87952 | I17: 0.718816 | J17: =(H17-I17)/H17 -> 0.18271785
C18: 8 | D18: 1 | E18: 2048 | F18: 16 | G18: 1 | H18: 0.094298 | I18: 0.088422 | J18: =(H18-I18)/H18 -> 0.062313093
... C35: 20 | D35: 1 | E35: 2048 | F35: 16 | G35: 4095 | H35: 4.186022 | I35: 3.318112 | J35: =(H35-I35)/H35 -> 0.20733527
B36: encoder | C36: 1 | D36: 1 | E36: 2048 | F36: 16 | G36: 0 | H36: 0.039072 | I36: 0.037248 | J36: =(H36-I36)/H36 -> 0.046683047
C37: 1 | D37: 128 | E37: 2048 | F37: 16 | G37: 0 | H37: 0.060109 | I37: 0.05753 | J37: =(H37-I37)/H37 -> 0.042905389
C38: 1 | D38: 512 | E38: 2048 | F38: 16 | G38: 0 | H38: 0.305875 | I38: 0.267731 | J38: =(H38-I38)/H38 -> 0.12470454
C39: 1 | D39: 1024 | E39: 2048 | F39: 16 | G39: 0 | H39: 1.295181 | I39: 1.185568 | J39: =(H39-I39)/H39 -> 0.084631414
C40: 1 | D40: 2048 | E40: 2048 | F40: 16 | G40: 0 | H40: 4.805178 | I40: 4.427084 | J40: =(H40-I40)/H40 -> 0.078684702
C41: 1 | D41: 4096 | E41: 2048 | F41: 16 | G41: 0 | H41: 18.170298 | I41: 16.684359 | J41: =(H41-I41)/H41 -> 0.081778461
C42: 4 | D42: 1 | E42: 2048 | F42: 16 | G42: 0 | H42: 0.062522 | I42: 0.058099 | J42: =(H42-I42)/H42 -> 0.070743098
C43: 4 | D43: 128 | E43: 2048 | F43: 16 | G43: 0 | H43: 0.158842 | I43: 0.148506 | J43: =(H43-I43)/H43 -> 0.065070951
C44: 4 | D44: 512 | E44: 2048 | F44: 16 | G44: 0 | H44: 1.31776 | I44: 1.252032 | J44: =(H44-I44)/H44 -> 0.049878582
C45: 4 | D45: 1024 | E45: 2048 | F45: 16 | G45: 0 | H45: 5.327539 | I45: 4.937267 | J45: =(H45-I45)/H45 -> 0.073255588
C46: 4 | D46: 2048 | E46: 2048 | F46: 16 | G46: 0 | H46: 20.025063 | I46: 19.285875 | J46: =(H46-I46)/H46 -> 0.036913142
C47: 4 | D47: 4096 | E47: 2048 | F47: 16 | G47: 0 | H47: 77.035248 | I47: 71.800728 | J47: =(H47-I47)/H47 -> 0.067949674
C48: 8 | D48: 1 | E48: 2048 | F48: 16 | G48: 0 | H48: 0.09385 | I48: 0.088378 | J48: =(H48-I48)/H48 -> 0.058305807
... C57: 20 | D57: 128 | E57: 2048 | F57: 16 | G57: 0 | H57: 0.725811 | I57: 0.706368 | J57: =(H57-I57)/H57 -> 0.026787965

Sheet score_GMB_HBM
B3: brsw: 1680
H4: uma_hbm | I4: uma_gmb | L4: numa_hbm | M4: numa_gmb
C5: N | D5: H | E5: W | F5: spc_num | G5: seq_idx | H5: 优化前ms | I5: 优化后ms | J5: 收益 | L5: 优化前ms | M5: 优化后ms | N5: 收益
B6: decoder | C6: 1 | D6: 1 | E6: 2048 | F6: 16 | G6: 1 | H6: 0.038598 | I6: 0.032275 | J6: =(H6-I6)/H6 -> 0.16381678 | L6: 0.036698 | M6: 0.036602 | N6: =(L6-M6)/L6 -> 0.0026159464
C7: 1 | D7: 1 | E7: 2048 | F7: 16 | G7: 127 | H7: 0.040794 | I7: 0.041062 | J7: =(H7-I7)/H7 -> -0.0065695936 | L7: 0.039174 | M7: 0.038995 | N7: =(L7-M7)/L7 -> 0.0045693572
C8: 1 | D8: 1 | E8: 2048 | F8: 16 | G8: 255 | H8: 0.048109 | I8: 0.048211 | J8: =(H8-I8)/H8 -> -0.0021201854 | L8: 0.044198 | M8: 0.044237 | N8: =(L8-M8)/L8 -> -0.00088239287
C9: 1 | D9: 1 | E9: 2048 | F9: 16 | G9: 511 | H9: 0.063392 | I9: 0.06359 | J9: =(H9-I9)/H9 -> -0.0031234225 | L9: 0.054989 | M9: 0.055059 | N9: =(L9-M9)/L9 -> -0.0012729819
C10: 1 | D10: 1 | E10: 2048 | F10: 16 | G10: 1023 | H10: 0.095258 | I10: 0.093427 | J10: =(H10-I10)/H10 -> 0.019221483 | L10: 0.072678 | M10: 0.072045 | N10: =(L10-M10)/L10 -> 0.0087096508
C11: 1 | D11: 1 | E11: 2048 | F11: 16 | G11: 2047 | H11: 0.145402 | I11: 0.142093 | J11: =(H11-I11)/H11 -> 0.022757596 | L11: 0.110266 | M11: 0.108589 | N11: =(L11-M11)/L11 -> 0.015208677
C12: 1 | D12: 1 | E12: 2048 | F12: 16 | G12: 4095 | H12: 0.245632 | I12: 0.244403 | J12: =(H12-I12)/H12 -> 0.0050034197 | L12: 0.188083 | M12: 0.181427 | N12: =(L12-M12)/L12 -> 0.035388632
C13: 4 | D13: 1 | E13: 2048 | F13: 16 | G13: 1 | H13: 0.060826 | I13: 0.060486 | J13: =(H13-I13)/H13 -> 0.0055897149 | L13: 0.05792 | M13: 0.05753 | N13: =(L13-M13)/L13 -> 0.0067334254
C14: 4 | D14: 1 | E14: 2048 | F14: 16 | G14: 127 | H14: 0.068525 | I14: 0.068186 | J14: =(H14-I14)/H14 -> 0.0049470996 | L14: 0.066426 | M14: 0.065862 | N14: =(L14-M14)/L14 -> 0.0084906513
C15: 4 | D15: 1 | E15: 2048 | F15: 16 | G15: 255 | H15: 0.094298 | I15: 0.092928 | J15: =(H15-I15)/H15 -> 0.01452841 | L15: 0.088589 | M15: 0.08793 | N15: =(L15-M15)/L15 -> 0.0074388468
C16: 4 | D16: 1 | E16: 2048 | F16: 16 | G16: 511 | H16: 0.148378 | I16: 0.144301 | J16: =(H16-I16)/H16 -> 0.027477119 | L16: 0.134502 | M16: 0.133606 | N16: =(L16-M16)/L16 -> 0.006661611
C17: 4 | D17: 1 | E17: 2048 | F17: 16 | G17: 1022 | H17: 0.264352 | I17: 0.255418 | J17: =(H17-I17)/H17 -> 0.033795848 | L17: 0.221728 | M17: 0.217178 | N17: =(L17-M17)/L17 -> 0.020520638
C18: 4 | D18: 1 | E18: 2048 | F18: 16 | G18: 2047 | H18: 0.473325 | I18: 0.455994 | J18: =(H18-I18)/H18 -> 0.036615433 | L18: 0.401011 | M18: 0.38016 | N18: =(L18-M18)/L18 -> 0.05199608
... C40: 20 | D40: 1 | E40: 2048 | F40: 16 | G40: 4095 | H40: 4.288915 | I40: 4.106534 | J40: =(H40-I40)/H40 -> 0.042523808 | L40: 3.31911 | M40: 3.211846 | N40: =(L40-M40)/L40 -> 0.032317097
B41: encoder | C41: 1 | D41: 1 | E41: 2048 | F41: 16 | G41: 0 | H41: 0.038835 | I41: 0.038842 | J41: =(H41-I41)/H41 -> -0.00018024977 | L41: 0.036954 | M41: 0.036941 | N41: =(L41-M41)/L41 -> 0.00035178871
C42: 1 | D42: 128 | E42: 2048 | F42: 16 | G42: 0 | H42: 0.060653 | I42: 0.060339 | J42: =(H42-I42)/H42 -> 0.0051769904 | L42: 0.057453 | M42: 0.057466 | N42: =(L42-M42)/L42 -> -0.00022627191
C43: 1 | D43: 256 | E43: 2048 | F43: 16 | G43: 0 | H43: 0.115053 | I43: 0.114355 | J43: =(H43-I43)/H43 -> 0.0060667692 | L43: 0.106022 | M43: 0.104435 | N43: =(L43-M43)/L43 -> 0.014968591
C44: 1 | D44: 512 | E44: 2048 | F44: 16 | G44: 0 | H44: 0.305914 | I44: 0.297594 | J44: =(H44-I44)/H44 -> 0.027197186 | L44: 0.268947 | M44: 0.262854 | N44: =(L44-M44)/L44 -> 0.022655021
C45: 1 | D45: 1024 | E45: 2048 | F45: 16 | G45: 0 | H45: 1.258605 | I45: 0.97904 | J45: =(H45-I45)/H45 -> 0.22212291 | L45: 1.186106 | M45: 0.867251 | N45: =(L45-M45)/L45 -> 0.26882505
C46: 1 | D46: 2048 | E46: 2048 | F46: 16 | G46: 0 | H46: 4.791552 | I46: 4.12807 | J46: =(H46-I46)/H46 -> 0.13846912 | L46: 4.428512 | M46: 3.746886 | N46: =(L46-M46)/L46 -> 0.15391761
C47: 1 | D47: 4096 | E47: 2048 | F47: 16 | G47: 0 | H47: 18.169683 | I47: 15.25984 | J47: =(H47-I47)/H47 -> 0.16014825 | L47: 16.68288 | M47: 13.934208 | N47: =(L47-M47)/L47 -> 0.16476004
C48: 4 | D48: 1 | E48: 2048 | F48: 16 | G48: 0 | H48: 0.060659 | I48: 0.060102 | J48: =(H48-I48)/H48 -> 0.0091824791 | L48: 0.057901 | M48: 0.057274 | N48: =(L48-M48)/L48 -> 0.010828829
C49: 4 | D49: 128 | E49: 2048 | F49: 16 | G49: 0 | H49: 0.147558 | I49: 0.14128 | J49: =(H49-I49)/H49 -> 0.042545982 | L49: 0.147821 | M49: 0.146208 | N49: =(L49-M49)/L49 -> 0.010911846
C50: 4 | D50: 256 | E50: 2048 | F50: 16 | G50: 0 | H50: 0.37239 | I50: 0.358163 | J50: =(H50-I50)/H50 -> 0.03820457 | L50: 0.37143 | M50: 0.37216 | N50: =(L50-M50)/L50 -> -0.0019653771
C51: 4 | D51: 512 | E51: 2048 | F51: 16 | G51: 0 | H51: 1.290976 | I51: 1.11056 | J51: =(H51-I51)/H51 -> 0.13975163 | L51: 1.252147 | M51: 1.070579 | N51: =(L51-M51)/L51 -> 0.14500534
C52: 4 | D52: 1024 | E52: 2048 | F52: 16 | G52: 0 | H52: 5.315674 | I52: 4.434221 | J52: =(H52-I52)/H52 -> 0.16582149 | L52: 4.937562 | M52: 4.047814 | N52: =(L52-M52)/L52 -> 0.18019986
C53: 4 | D53: 2048 | E53: 2048 | F53: 16 | G53: 0 | H53: 20.085176 | I53: 15.862029 | J53: =(H53-I53)/H53 -> 0.21026189 | L53: 19.29104 | M53: 14.454105 | N53: =(L53-M53)/L53 -> 0.2507348
... C66: 20 | D66: 128 | E66: 2048 | F66: 16 | G66: 0 | H66: 0.709926 | I66: 0.63079 | J66: =(H66-I66)/H66 -> 0.11147077 | L66: 0.72688 | M66: 0.637658 | N66: =(L66-M66)/L66 -> 0.12274653

Sheet unroll
B3: brsw: 1680
H4: UMAFP32 | K4: NUMAFP32 | O4: UMA FP32 | R4: NUMAFP32
C5: N | D5: H | E5: W | F5: spc_num | G5: seq_idx | H5: unroll前ms | I5: unroll后ms | J5: 收益 | K5: unroll前ms | L5: unroll后ms | M5: 收益 | O5: unroll前ms | P5: unroll后ms | Q5: 收益 | R5: unroll前ms | S5: unroll后ms | T5: 收益
B6: decoder | C6: 1 | D6: 1 | E6: 2048 | F6: 16 | G6: 1 | H6: 0.038003 | I6: 0.038867 | J6: =(H6-I6)/H6 -> -0.022735047 | K6: 0.036717 | L6: 0.037286 | M6: =(K6-L6)/K6 -> -0.015496909 | O6: 0.040698 | P6: 0.040147 | Q6: =(O6-P6)/O6 -> 0.013538749 | R6: 0.037786 | S6: 0.037331 | T6: =(R6-S6)/R6 -> 0.012041497
C7: 1 | D7: 1 | E7: 2048 | F7: 16 | G7: 127 | H7: 0.040493 | I7: 0.041747 | J7: =(H7-I7)/H7 -> -0.030968316 | K7: 0.039258 | L7: 0.03968 | M7: =(K7-L7)/K7 -> -0.010749401 | O7: 0.044294 | P7: 0.044147 | Q7: =(O7-P7)/O7 -> 0.0033187339 | R7: 0.041107 | S7: 0.04048 | T7: =(R7-S7)/R7 -> 0.015252877
C8: 1 | D8: 1 | E8: 2048 | F8: 16 | G8: 255 | H8: 0.047968 | I8: 0.049613 | J8: =(H8-I8)/H8 -> -0.034293696 | K8: 0.044058 | L8: 0.044518 | M8: =(K8-L8)/K8 -> -0.010440783 | O8: 0.054419 | P8: 0.054182 | Q8: =(O8-P8)/O8 -> 0.0043550966 | R8: 0.047053 | S8: 0.046426 | T8: =(R8-S8)/R8 -> 0.013325399
C9: 1 | D9: 1 | E9: 2048 | F9: 16 | G9: 511 | H9: 0.061875 | I9: 0.065107 | J9: =(H9-I9)/H9 -> -0.052234343 | K9: 0.053926 | L9: 0.054746 | M9: =(K9-L9)/K9 -> -0.015206023 | O9: 0.07248 | P9: 0.071034 | Q9: =(O9-P9)/O9 -> 0.019950331 | R9: 0.058253 | S9: 0.056403 | T9: =(R9-S9)/R9 -> 0.031758021
C10: 1 | D10: 1 | E10: 2048 | F10: 16 | G10: 1023 | H10: 0.087744 | I10: 0.087859 | J10: =(H10-I10)/H10 -> -0.0013106309 | K10: 0.072262 | L10: 0.067526 | M10: =(K10-L10)/K10 -> 0.065539288 | O10: 0.103168 | P10: 0.104141 | Q10: =(O10-P10)/O10 -> -0.009431219 | R10: 0.078995 | S10: 0.075194 | T10: =(R10-S10)/R10 -> 0.048116969
C11: 1 | D11: 1 | E11: 2048 | F11: 16 | G11: 2047 | H11: 0.134202 | I11: 0.13175 | J11: =(H11-I11)/H11 -> 0.018270965 | K11: 0.108774 | L11: 0.09888 | M11: =(K11-L11)/K11 -> 0.090959237 | O11: 0.16391 | P11: 0.163034 | Q11: =(O11-P11)/O11 -> 0.0053443963 | R11: 0.120198 | S11: 0.112762 | T11: =(R11-S11)/R11 -> 0.06186459
C12: 1 | D12: 1 | E12: 2048 | F12: 16 | G12: 4095 | H12: 0.22503 | I12: 0.216262 | J12: =(H12-I12)/H12 -> 0.038963694 | K12: 0.181651 | L12: 0.160896 | M12: =(K12-L12)/K12 -> 0.11425756 | O12: 0.287482 | P12: 0.2792 | Q12: =(O12-P12)/O12 -> 0.02880876 | R12: 0.202285 | S12: 0.188384 | T12: =(R12-S12)/R12 -> 0.068719875
C13: 4 | D13: 1 | E13: 2048 | F13: 16 | G13: 1 | H13: 0.058611 | I13: 0.059616 | J13: =(H13-I13)/H13 -> -0.017146952 | K13: 0.058477 | L13: 0.058259 | M13: =(K13-L13)/K13 -> 0.0037279614 | O13: 0.067194 | P13: 0.06665 | Q13: =(O13-P13)/O13 -> 0.0080959609 | R13: 0.064077 | S13: 0.062707 | T13: =(R13-S13)/R13 -> 0.021380527
C14: 4 | D14: 1 | E14: 2048 | F14: 16 | G14: 127 | H14: 0.066541 | I14: 0.067878 | J14: =(H14-I14)/H14 -> -0.020092875 | K14: 0.065952 | L14: 0.06585 | M14: =(K14-L14)/K14 -> 0.0015465793 | O14: 0.078093 | P14: 0.077459 | Q14: =(O14-P14)/O14 -> 0.0081185253 | R14: 0.072486 | S14: 0.071053 | T14: =(R14-S14)/R14 -> 0.019769335
C15: 4 | D15: 1 | E15: 2048 | F15: 16 | G15: 255 | H15: 0.090854 | I15: 0.092781 | J15: =(H15-I15)/H15 -> -0.021209853 | K15: 0.086227 | L15: 0.08592 | M15: =(K15-L15)/K15 -> 0.0035603697 | O15: 0.113702 | P15: 0.112922 | Q15: =(O15-P15)/O15 -> 0.0068600376 | R15: 0.094438 | S15: 0.093472 | T15: =(R15-S15)/R15 -> 0.010228933
C16: 4 | D16: 1 | E16: 2048 | F16: 16 | G16: 511 | H16: 0.141376 | I16: 0.143379 | J16: =(H16-I16)/H16 -> -0.014167893 | K16: 0.130138 | L16: 0.130195 | M16: =(K16-L16)/K16 -> -0.00043799659 | O16: 0.178637 | P16: 0.174413 | Q16: =(O16-P16)/O16 -> 0.023645717 | R16: 0.141504 | S16: 0.134118 | T16: =(R16-S16)/R16 -> 0.052196404
C17: 4 | D17: 1 | E17: 2048 | F17: 16 | G17: 1022 | H17: 0.238566 | I17: 0.231315 | J17: =(H17-I17)/H17 -> 0.030394105 | K17: 0.217408 | L17: 0.193446 | M17: =(K17-L17)/K17 -> 0.11021674 | O17: 0.302112 | P17: 0.294048 | Q17: =(O17-P17)/O17 -> 0.026692088 | R17: 0.231462 | S17: 0.217024 | T17: =(R17-S17)/R17 -> 0.06237741
C18: 4 | D18: 1 | E18: 2048 | F18: 16 | G18: 2047 | H18: 0.418086 | I18: 0.395616 | J18: =(H18-I18)/H18 -> 0.053744923 | K18: 0.376966 | L18: 0.326035 | M18: =(K18-L18)/K18 -> 0.13510768 | O18: 0.545395 | P18: 0.528096 | Q18: =(O18-P18)/O18 -> 0.031718296 | R18: 0.414278 | S18: 0.388947 | T18: =(R18-S18)/R18 -> 0.061144932
... C40: 20 | D40: 1 | E40: 2048 | F40: 16 | G40: 4095 | H40: 3.749229 | I40: 3.463398 | J40: =(H40-I40)/H40 -> 0.076237274 | K40: 3.221453 | L40: 2.808045 | M40: =(K40-L40)/K40 -> 0.12832967 | O40: 5.082726 | P40: 4.871987 | Q40: =(O40-P40)/O40 -> 0.041461806 | R40: 3.790029 | S40: 3.554611 | T40: =(R40-S40)/R40 -> 0.062115092
B41: encoder | C41: 1 | D41: 1 | E41: 2048 | F41: 16 | G41: 0 | H41: 0.03863 | I41: 0.039341 | J41: =(H41-I41)/H41 -> -0.018405384 | K41: 0.036922 | L41: 0.037779 | M41: =(K41-L41)/K41 -> -0.023211094 | O41: 0.040826 | P41: 0.040666 | Q41: =(O41-P41)/O41 -> 0.0039190712 | R41: 0.038112 | S41: 0.037638 | T41: =(R41-S41)/R41 -> 0.012437028
C42: 1 | D42: 128 | E42: 2048 | F42: 16 | G42: 0 | H42: 0.05959 | I42: 0.06023 | J42: =(H42-I42)/H42 -> -0.010740057 | K42: 0.057715 | L42: 0.057702 | M42: =(K42-L42)/K42 -> 0.00022524474 | O42: 0.06576 | P42: 0.064518 | Q42: =(O42-P42)/O42 -> 0.018886861 | R42: 0.06167 | S42: 0.061338 | T42: =(R42-S42)/R42 -> 0.0053834928
C43: 1 | D43: 256 | E43: 2048 | F43: 16 | G43: 0 | H43: 0.112435 | I43: 0.114995 | J43: =(H43-I43)/H43 -> -0.022768711 | K43: 0.104301 | L43: 0.104474 | M43: =(K43-L43)/K43 -> -0.001658661 | O43: 0.134048 | P43: 0.133837 | Q43: =(O43-P43)/O43 -> 0.001574063 | R43: 0.113434 | S43: 0.112845 | T43: =(R43-S43)/R43 -> 0.0051924467
C44: 1 | D44: 512 | E44: 2048 | F44: 16 | G44: 0 | H44: 0.295718 | I44: 0.300672 | J44: =(H44-I44)/H44 -> -0.016752447 | K44: 0.261946 | L44: 0.263104 | M44: =(K44-L44)/K44 -> -0.0044207585 | O44: 0.357286 | P44: 0.350067 | Q44: =(O44-P44)/O44 -> 0.020205102 | R44: 0.309037 | S44: 0.295181 | T44: =(R44-S44)/R44 -> 0.044836055
C45: 1 | D45: 1024 | E45: 2048 | F45: 16 | G45: 0 | H45: 0.983046 | I45: 0.93353 | J45: =(H45-I45)/H45 -> 0.050369973 | K45: 0.867258 | L45: 0.796384 | M45: =(K45-L45)/K45 -> 0.081721933 | O45: 1.242432 | P45: 1.197619 | Q45: =(O45-P45)/O45 -> 0.036068775 | R45: 1.102029 | S45: 1.052192 | T45: =(R45-S45)/R45 -> 0.045222948
C46: 1 | D46: 2048 | E46: 2048 | F46: 16 | G46: 0 | H46: 4.114253 | I46: 3.903552 | J46: =(H46-I46)/H46 -> 0.051212456 | K46: 3.755283 | L46: 3.442643 | M46: =(K46-L46)/K46 -> 0.083253379 | O46: 4.750208 | P46: 4.568032 | Q46: =(O46-P46)/O46 -> 0.038351163 | R46: 4.088839 | S46: 3.887757 | T46: =(R46-S46)/R46 -> 0.049178263
C47: 1 | D47: 4096 | E47: 2048 | F47: 16 | G47: 0 | H47: 15.21552 | I47: 14.34046 | J47: =(H47-I47)/H47 -> 0.057511015 | K47: 13.971667 | L47: 12.754458 | M47: =(K47-L47)/K47 -> 0.087119812 | O47: 18.260658 | P47: 17.564754 | Q47: =(O47-P47)/O47 -> 0.03810947 | R47: 15.497926 | S47: 14.692435 | T47: =(R47-S47)/R47 -> 0.051974116
C48: 4 | D48: 1 | E48: 2048 | F48: 16 | G48: 0 | H48: 0.05833 | I48: 0.059507 | J48: =(H48-I48)/H48 -> -0.020178296 | K48: 0.057888 | L48: 0.057715 | M48: =(K48-L48)/K48 -> 0.0029885296 | O48: 0.067251 | P48: 0.06649 | Q48: =(O48-P48)/O48 -> 0.011315817 | R48: 0.064109 | S48: 0.062509 | T48: =(R48-S48)/R48 -> 0.024957494
C49: 4 | D49: 128 | E49: 2048 | F49: 16 | G49: 0 | H49: 0.138957 | I49: 0.139526 | J49: =(H49-I49)/H49 -> -0.0040947919 | K49: 0.145651 | L49: 0.146298 | M49: =(K49-L49)/K49 -> -0.0044421254 | O49: 0.156576 | P49: 0.154598 | Q49: =(O49-P49)/O49 -> 0.012632843 | R49: 0.158918 | S49: 0.15705 | T49: =(R49-S49)/R49 -> 0.01175449
C50: 4 | D50: 256 | E50: 2048 | F50: 16 | G50: 0 | H50: 0.352486 | I50: 0.357434 | J50: =(H50-I50)/H50 -> -0.014037437 | K50: 0.367322 | L50: 0.371098 | M50: =(K50-L50)/K50 -> -0.010279809 | O50: 0.439648 | P50: 0.438829 | Q50: =(O50-P50)/O50 -> 0.0018628539 | R50: 0.41056 | S50: 0.412858 | T50: =(R50-S50)/R50 -> -0.005597233
C51: 4 | D51: 512 | E51: 2048 | F51: 16 | G51: 0 | H51: 1.111782 | I51: 1.133254 | J51: =(H51-I51)/H51 -> -0.019313139 | K51: 1.063757 | L51: 1.069658 | M51: =(K51-L51)/K51 -> -0.0055473195 | O51: 1.465549 | P51: 1.40953 | Q51: =(O51-P51)/O51 -> 0.038223901 | R51: 1.245466 | S51: 1.198016 | T51: =(R51-S51)/R51 -> 0.03809819
C52: 4 | D52: 1024 | E52: 2048 | F52: 16 | G52: 0 | H52: 4.461107 | I52: 4.265523 | J52: =(H52-I52)/H52 -> 0.043842033 | K52: 4.051718 | L52: 3.773101 | M52: =(K52-L52)/K52 -> 0.068765151 | O52: 5.314317 | P52: 5.092916 | Q52: =(O52-P52)/O52 -> 0.041661233 | R52: 4.411283 | S52: 4.2112 | T52: =(R52-S52)/R52 -> 0.045357099
C53: 4 | D53: 2048 | E53: 2048 | F53: 16 | G53: 0 | H53: 16.075272 | I53: 15.267879 | J53: =(H53-I53)/H53 -> 0.050225775 | K53: 14.474118 | L53: 13.277063 | M53: =(K53-L53)/K53 -> 0.082703139 | O53: 20.181658 | P53: 19.256378 | Q53: =(O53-P53)/O53 -> 0.045847571 | R53: 15.925088 | S53: 15.11472 | T53: =(R53-S53)/R53 -> 0.050886249
... C66: 20 | D66: 128 | E66: 2048 | F66: 16 | G66: 0 | H66: 0.605389 | I66: 0.610042 | J66: =(H66-I66)/H66 -> -0.0076859672 | K66: 0.635072 | L66: 0.634381 | M66: =(K66-L66)/K66 -> 0.0010880656 | O66: 0.716512 | P66: 0.715686 | Q66: =(O66-P66)/O66 -> 0.0011528069 | R66: 0.70704 | S66: 0.699488 | T66: =(R66-S66)/R66 -> 0.01068115

Sheet vcore
B2: brsw: 1718
C4: N | D4: H | E4: W | F4: spc_num | G4: seq_idx | H4: tcore | I4: vcore实现1 | J4: 收益 | K4: vcore实现2 | L4: 收益
B5: decoder | C5: 1 | D5: 1 | E5: 2048 | F5: 16 | G5: 1 | H5: 0.031027 | I5: 0.037568 | J5: =(H5-I5)/H5 -> -0.21081639 | K5: 0.040064 | L5: =(H5-K5)/H5 -> -0.29126245
C6: 1 | D6: 1 | E6: 2048 | F6: 16 | G6: 127 | H6: 0.03641 | I6: 0.072678 | J6: =(H6-I6)/H6 -> -0.99609997 | K6: 0.04416 | L6: =(H6-K6)/H6 -> -0.21285361
C7: 1 | D7: 1 | E7: 2048 | F7: 16 | G7: 255 | H7: 0.046752 | I7: 0.119456 | J7: =(H7-I7)/H7 -> -1.5550992 | K7: 0.062278 | L7: =(H7-K7)/H7 -> -0.33209274
C8: 1 | D8: 1 | E8: 2048 | F8: 16 | G8: 511 | H8: 0.068954 | I8: 0.216346 | J8: =(H8-I8)/H8 -> -2.137541 | K8: 0.091667 | L8: =(H8-K8)/H8 -> -0.32939351
C9: 1 | D9: 1 | E9: 2048 | F9: 16 | G9: 1023 | H9: 0.097907 | I9: 0.402803 | J9: =(H9-I9)/H9 -> -3.1141389 | K9: 0.155283 | L9: =(H9-K9)/H9 -> -0.58602551
C10: 1 | D10: 1 | E10: 2048 | F10: 16 | G10: 2047 | H10: 0.154893 | I10: 0.786931 | J10: =(H10-I10)/H10 -> -4.0804814 | K10: 0.285837 | L10: =(H10-K10)/H10 -> -0.84538359
C11: 1 | D11: 1 | E11: 2048 | F11: 16 | G11: 4095 | H11: 0.272979 | I11: 1.556851 | J11: =(H11-I11)/H11 -> -4.7031896 | K11: 0.544058 | L11: =(H11-K11)/H11 -> -0.99303976
C12: 4 | D12: 1 | E12: 2048 | F12: 16 | G12: 1 | H12: 0.053901 | I12: 0.051398 | J12: =(H12-I12)/H12 -> 0.046436986 | K12: 0.053357 | L12: =(H12-K12)/H12 -> 0.010092577
C13: 4 | D13: 1 | E13: 2048 | F13: 16 | G13: 127 | H13: 0.067219 | I13: 0.086739 | J13: =(H13-I13)/H13 -> -0.29039409 | K13: 0.056429 | L13: =(H13-K13)/H13 -> 0.16052009
C14: 4 | D14: 1 | E14: 2048 | F14: 16 | G14: 255 | H14: 0.10288 | I14: 0.14695 | J14: =(H14-I14)/H14 -> -0.42836314 | K14: 0.083424 | L14: =(H14-K14)/H14 -> 0.18911353
C15: 4 | D15: 1 | E15: 2048 | F15: 16 | G15: 511 | H15: 0.161261 | I15: 0.263142 | J15: =(H15-I15)/H15 -> -0.63177706 | K15: 0.133888 | L15: =(H15-K15)/H15 -> 0.16974346
C16: 4 | D16: 1 | E16: 2048 | F16: 16 | G16: 1022 | H16: 0.27977 | I16: 0.49065 | J16: =(H16-I16)/H16 -> -0.75376202 | K16: 0.237222 | L16: =(H16-K16)/H16 -> 0.15208207
C17: 4 | D17: 1 | E17: 2048 | F17: 16 | G17: 2047 | H17: 0.513382 | I17: 0.953357 | J17: =(H17-I17)/H17 -> -0.85701291 | K17: 0.446656 | L17: =(H17-K17)/H17 -> 0.12997339
... C39: 20 | D39: 1 | E39: 2048 | F39: 16 | G39: 4095 | H39: 4.753139 | I39: 9.99191 | J39: =(H39-I39)/H39 -> -1.1021708 | K39: 5.249658 | L39: =(H39-K39)/H39 -> -0.10446128

Sheet 模型性能1113
C3: encoder
B4: encoder | C4: N | D4: H | E4: W | F4: spc_num | G4: 时间 | H4: 模型
C5: 1 | D5: 135 | E5: 4096 | F5: 16 | G5: 0.132826ms. | H5: chatglm2 6B
C6: 1 | D6: 135 | E6: 4096 | F6: 16 | G6: 0.116333ms. | H6: llama1_7B/baichuan1_7B
C7: 1 | D7: 135 | E7: 2048 | F7: 16 | G7: 0.085389ms. | H7: llama2_70B(4卡)
C8: 1 | D8: 135 | E8: 5120 | F8: 16 | G8: 0.157830ms. | H8: llama1_13B
C9: 1 | D9: 135 | E9: 2560 | F9: 16 | G9: 0.112602ms. | H9: llama1_13B/baichuan1_13B(2卡)
C10: 1 | D10: 135 | E10: 2048 | F10: 16 | G10: 0.071091ms. | H10: llama2_70B(4卡)
C11: 1 | D11: 511 | E11: 4096 | F11: 16 | G11: 0.656934ms. | H11: chatglm2 6B
C12: 1 | D12: 511 | E12: 4096 | F12: 16 | G12: 0.561632ms. | H12: llama1_7B/baichuan1_7B
C13: 1 | D13: 511 | E13: 2048 | F13: 16 | G13: 0.366118ms. | H13: llama2_70B(4卡)
C14: 1 | D14: 511 | E14: 5120 | F14: 16 | G14: 0.819328ms. | H14: llama1_13B
C15: 1 | D15: 511 | E15: 2560 | F15: 16 | G15: 0.529101ms. | H15: llama1_13B/baichuan1_13B(2卡)
C16: 1 | D16: 511 | E16: 2048 | F16: 16 | G16: 0.303091ms. | H16: llama2_70B(4卡)
... C58: 20 | D58: 512 | E58: 2048 | F58: 16 | G58: 6.834259ms. | H58: llama2_70B(4卡)
B59: decoder | C59: 1 | D59: 135 | E59: 4096 | F59: 16 | G59: 0.062470ms. | H59: chatglm2 6B
C60: 1 | D60: 135 | E60: 4096 | F60: 16 | G60: 0.055552ms. | H60: llama1_7B/baichuan1_7B
C61: 1 | D61: 135 | E61: 2048 | F61: 16 | G61: 0.046726ms. | H61: llama2_70B(4卡)
C62: 1 | D62: 135 | E62: 5120 | F62: 16 | G62: 0.066074ms. | H62: llama1_13B
C63: 1 | D63: 135 | E63: 2560 | F63: 16 | G63: 0.051456ms. | H63: llama1_13B/baichuan1_13B(2卡)
C64: 1 | D64: 135 | E64: 2048 | F64: 16 | G64: 0.035987ms. | H64: llama2_70B(4卡)
C65: 1 | D65: 511 | E65: 4096 | F65: 16 | G65: 0.097638ms. | H65: chatglm2 6B
C66: 1 | D66: 511 | E66: 4096 | F66: 16 | G66: 0.085363ms. | H66: llama1_7B/baichuan1_7B
C67: 1 | D67: 511 | E67: 2048 | F67: 16 | G67: 0.061901ms. | H67: llama2_70B(4卡)
C68: 1 | D68: 511 | E68: 5120 | F68: 16 | G68: 0.105018ms. | H68: llama1_13B
C69: 1 | D69: 511 | E69: 2560 | F69: 16 | G69: 0.078074ms. | H69: llama1_13B/baichuan1_13B(2卡)
C70: 1 | D70: 511 | E70: 2048 | F70: 16 | G70: 0.049562ms. | H70: llama2_70B(4卡)
C71: 1 | D71: 1024 | E71: 4096 | F71: 16 | G71: 0.168781ms. | H71: chatglm2 6B
... C112: 20 | D112: 512 | E112: 2048 | F112: 16 | G112: 0.620781ms. | H112: llama2_70B(4卡)

Sheet exp
B3: encoder | C3: N | D3: H | E3: W | F3: spc_num | G3: 优化前 | H3: exp优化 | I3: 收益 | J3: 模型
C4: 1 | D4: 135 | E4: 4096 | F4: 16 | G4: 0.132826 | H4: 0.126368 | I4: =(G4-H4)/G4 -> 0.048619999 | J4: chatglm2 6B | L4: 0.129491 | P4: 0.125792 | R4: =(L4-P4)/L4 -> 0.028565692
C5: 1 | D5: 135 | E5: 4096 | F5: 16 | G5: 0.116333 | H5: 0.110195 | I5: =(G5-H5)/G5 -> 0.052762329 | J5: llama1_7B/baichuan1_7B | L5: 0.110131 | P5: 0.110042 | R5: =(L5-P5)/L5 -> 0.0008081285
C6: 1 | D6: 135 | E6: 2048 | F6: 16 | G6: 0.085389 | H6: 0.083232 | I6: =(G6-H6)/G6 -> 0.025260865 | J6: llama2_70B(4卡) | L6: 0.082022 | P6: 0.080013 | R6: =(L6-P6)/L6 -> 0.024493429
C7: 1 | D7: 135 | E7: 5120 | F7: 16 | G7: 0.15783 | H7: 0.147046 | I7: =(G7-H7)/G7 -> 0.068326681 | J7: llama1_13B | L7: 0.146138 | P7: 0.147642 | R7: =(L7-P7)/L7 -> -0.010291642
C8: 1 | D8: 135 | E8: 2560 | F8: 16 | G8: 0.112602 | H8: 0.107386 | I8: =(G8-H8)/G8 -> 0.046322445 | J8: llama1_13B/baichuan1_13B(2卡) | L8: 0.104294 | P8: 0.10601 | R8: =(L8-P8)/L8 -> -0.016453487
C9: 1 | D9: 135 | E9: 2048 | F9: 16 | G9: 0.071091 | H9: 0.067469 | I9: =(G9-H9)/G9 -> 0.050948784 | J9: llama2_70B(4卡) | L9: 0.069677 | P9: 0.067174 | R9: =(L9-P9)/L9 -> 0.035922901
C10: 1 | D10: 511 | E10: 4096 | F10: 16 | G10: 0.656934 | H10: 0.604102 | I10: =(G10-H10)/G10 -> 0.080422082 | J10: chatglm2 6B | L10: 0.609805 | P10: 0.601658 | R10: =(L10-P10)/L10 -> 0.013360009
C11: 1 | D11: 511 | E11: 4096 | F11: 16 | G11: 0.561632 | H11: 0.522067 | I11: =(G11-H11)/G11 -> 0.070446485 | J11: llama1_7B/baichuan1_7B | L11: 0.496768 | P11: 0.523987 | R11: =(L11-P11)/L11 -> -0.054792177
C12: 1 | D12: 511 | E12: 2048 | F12: 16 | G12: 0.366118 | H12: 0.333024 | I12: =(G12-H12)/G12 -> 0.090391622 | J12: llama2_70B(4卡) | L12: 0.352883 | P12: 0.32816 | R12: =(L12-P12)/L12 -> 0.070060048
C13: 1 | D13: 511 | E13: 5120 | F13: 16 | G13: 0.819328 | H13: 0.739872 | I13: =(G13-H13)/G13 -> 0.096977035 | J13: llama1_13B | L13: 0.72592 | P13: 0.7424 | R13: =(L13-P13)/L13 -> -0.022702226
C14: 1 | D14: 511 | E14: 2560 | F14: 16 | G14: 0.529101 | H14: 0.480096 | I14: =(G14-H14)/G14 -> 0.092619368 | J14: llama1_13B/baichuan1_13B(2卡) | L14: 0.470752 | P14: 0.480813 | R14: =(L14-P14)/L14 -> -0.021372187
C15: 1 | D15: 511 | E15: 2048 | F15: 16 | G15: 0.303091 | H15: 0.269222 | I15: =(G15-H15)/G15 -> 0.11174532 | J15: llama2_70B(4卡) | L15: 0.274515 | P15: 0.268288 | R15: =(L15-P15)/L15 -> 0.022683642
... C57: 20 | D57: 512 | E57: 2048 | F57: 16 | G57: 6.834259 | H57: 6.33113 | I57: =(G57-H57)/G57 -> 0.073618662 | J57: llama2_70B(4卡) | L57: 6.327309 | P57: 6.326464 | R57: =(L57-P57)/L57 -> 0.00013354808
B58: decoder | C58: 1 | D58: 135 | E58: 4096 | F58: 16 | G58: 0.06247 | H58: 0.061184 | I58: =(G58-H58)/G58 -> 0.020585881 | J58: chatglm2 6B | L58: 0.068858 | P58: 0.065638 | R58: =(L58-P58)/L58 -> 0.046762903 | S58: =(H58-P58)/H58 -> -0.07279681
C59: 1 | D59: 135 | E59: 4096 | F59: 16 | G59: 0.055552 | H59: 0.048902 | I59: =(G59-H59)/G59 -> 0.11970766 | J59: llama1_7B/baichuan1_7B | L59: 0.044627 | P59: 0.042214 | R59: =(L59-P59)/L59 -> 0.054070406 | S59: =(H59-P59)/H59 -> 0.13676332
C60: 1 | D60: 135 | E60: 2048 | F60: 16 | G60: 0.046726 | H60: 0.045856 | I60: =(G60-H60)/G60 -> 0.018619184 | J60: llama2_70B(4卡) | L60: 0.042477 | P60: 0.039469 | R60: =(L60-P60)/L60 -> 0.070814794 | S60: =(H60-P60)/H60 -> 0.13928385
C61: 1 | D61: 135 | E61: 5120 | F61: 16 | G61: 0.066074 | H61: 0.06128 | I61: =(G61-H61)/G61 -> 0.072555014 | J61: llama1_13B | L61: 0.055526 | P61: 0.051456 | R61: =(L61-P61)/L61 -> 0.073298995 | S61: =(H61-P61)/H61 -> 0.16031332
C62: 1 | D62: 135 | E62: 2560 | F62: 16 | G62: 0.051456 | H62: 0.048333 | I62: =(G62-H62)/G62 -> 0.060692631 | J62: llama1_13B/baichuan1_13B(2卡) | L62: 0.040678 | P62: 0.04105 | R62: =(L62-P62)/L62 -> -0.0091449924 | S62: =(H62-P62)/H62 -> 0.1506838
C63: 1 | D63: 135 | E63: 2048 | F63: 16 | G63: 0.035987 | H63: 0.034035 | I63: =(G63-H63)/G63 -> 0.05424181 | J63: llama2_70B(4卡) | L63: 0.030611 | P63: 0.031597 | R63: =(L63-P63)/L63 -> -0.032210643 | S63: =(H63-P63)/H63 -> 0.071632143
C64: 1 | D64: 511 | E64: 4096 | F64: 16 | G64: 0.097638 | H64: 0.09527 | I64: =(G64-H64)/G64 -> 0.024252852 | J64: chatglm2 6B | L64: 0.090195 | P64: 0.08809 | R64: =(L64-P64)/L64 -> 0.023338323 | S64: =(H64-P64)/H64 -> 0.075364753
C65: 1 | D65: 511 | E65: 4096 | F65: 16 | G65: 0.085363 | H65: 0.072499 | I65: =(G65-H65)/G65 -> 0.15069761 | J65: llama1_7B/baichuan1_7B | L65: 0.068198 | P65: 0.065466 | R65: =(L65-P65)/L65 -> 0.040059826 | S65: =(H65-P65)/H65 -> 0.097008235
C66: 1 | D66: 511 | E66: 2048 | F66: 16 | G66: 0.061901 | H66: 0.062272 | I66: =(G66-H66)/G66 -> -0.0059934411 | J66: llama2_70B(4卡) | L66: 0.06153 | P66: 0.055661 | R66: =(L66-P66)/L66 -> 0.095384365 | S66: =(H66-P66)/H66 -> 0.10616328
C67: 1 | D67: 511 | E67: 5120 | F67: 16 | G67: 0.105018 | H67: 0.09305 | I67: =(G67-H67)/G67 -> 0.11396142 | J67: llama1_13B | L67: 0.085024 | P67: 0.083642 | R67: =(L67-P67)/L67 -> 0.016254234 | S67: =(H67-P67)/H67 -> 0.10110693
C68: 1 | D68: 511 | E68: 2560 | F68: 16 | G68: 0.078074 | H68: 0.071398 | I68: =(G68-H68)/G68 -> 0.08550862 | J68: llama1_13B/baichuan1_13B(2卡) | L68: 0.066643 | P68: 0.065542 | R68: =(L68-P68)/L68 -> 0.016520865 | S68: =(H68-P68)/H68 -> 0.082019104
C69: 1 | D69: 511 | E69: 2048 | F69: 16 | G69: 0.049562 | H69: 0.044826 | I69: =(G69-H69)/G69 -> 0.09555708 | J69: llama2_70B(4卡) | L69: 0.04007 | P69: 0.040448 | R69: =(L69-P69)/L69 -> -0.0094334914 | S69: =(H69-P69)/H69 -> 0.097666533
C70: 1 | D70: 1024 | E70: 4096 | F70: 16 | G70: 0.168781 | H70: 0.15943 | I70: =(G70-H70)/G70 -> 0.055403156 | J70: chatglm2 6B | L70: 0.148877 | P70: 0.143718 | R70: =(L70-P70)/L70 -> 0.034652767 | S70: =(H70-P70)/H70 -> 0.098551088
... C111: 20 | D111: 512 | E111: 2048 | F111: 16 | G111: 0.620781 | H111: 0.541018 | I111: =(G111-H111)/G111 -> 0.12848815 | J111: llama2_70B(4卡) | L111: 0.463014 | P111: 0.4568 | R111: =(L111-P111)/L111 -> 0.01342076 | S111: =(H111-P111)/H111 -> 0.1556658

Sheet decoder
C3: N | D3: H | E3: W | F3: spc_num | G3: exp优化 | H3: float4改float1 | I3: 收益 | J3: 提前load vcache | K3: 收益 | L3: 模型
B4: decoder | C4: 1 | D4: 135 | E4: 4096 | F4: 16 | G4: 0.061184 | H4: 0.068858 | I4: =(G4-H4)/G4 -> -0.12542495 | J4: 0.065638 | K4: =(G4-J4)/G4 -> -0.07279681 | L4: chatglm2 6B
C5: 1 | D5: 135 | E5: 4096 | F5: 16 | G5: 0.048902 | H5: 0.044627 | I5: =(G5-H5)/G5 -> 0.087419737 | J5: 0.042214 | K5: =(G5-J5)/G5 -> 0.13676332 | L5: llama1_7B/baichuan1_7B
C6: 1 | D6: 135 | E6: 2048 | F6: 16 | G6: 0.045856 | H6: 0.042477 | I6: =(G6-H6)/G6 -> 0.073687195 | J6: 0.039469 | K6: =(G6-J6)/G6 -> 0.13928385 | L6: llama2_70B(4卡)
C7: 1 | D7: 135 | E7: 5120 | F7: 16 | G7: 0.06128 | H7: 0.055526 | I7: =(G7-H7)/G7 -> 0.093896867 | J7: 0.051456 | K7: =(G7-J7)/G7 -> 0.16031332 | L7: llama1_13B
C8: 1 | D8: 135 | E8: 2560 | F8: 16 | G8: 0.048333 | H8: 0.040678 | I8: =(G8-H8)/G8 -> 0.1583804 | J8: 0.04105 | K8: =(G8-J8)/G8 -> 0.1506838 | L8: llama1_13B/baichuan1_13B(2卡)
C9: 1 | D9: 135 | E9: 2048 | F9: 16 | G9: 0.034035 | H9: 0.030611 | I9: =(G9-H9)/G9 -> 0.10060232 | J9: 0.031597 | K9: =(G9-J9)/G9 -> 0.071632143 | L9: llama2_70B(4卡)
C10: 1 | D10: 511 | E10: 4096 | F10: 16 | G10: 0.09527 | H10: 0.090195 | I10: =(G10-H10)/G10 -> 0.053269655 | J10: 0.08809 | K10: =(G10-J10)/G10 -> 0.075364753 | L10: chatglm2 6B
C11: 1 | D11: 511 | E11: 4096 | F11: 16 | G11: 0.072499 | H11: 0.068198 | I11: =(G11-H11)/G11 -> 0.059324956 | J11: 0.065466 | K11: =(G11-J11)/G11 -> 0.097008235 | L11: llama1_7B/baichuan1_7B
C12: 1 | D12: 511 | E12: 2048 | F12: 16 | G12: 0.062272 | H12: 0.06153 | I12: =(G12-H12)/G12 -> 0.011915468 | J12: 0.055661 | K12: =(G12-J12)/G12 -> 0.10616328 | L12: llama2_70B(4卡)
C13: 1 | D13: 511 | E13: 5120 | F13: 16 | G13: 0.09305 | H13: 0.085024 | I13: =(G13-H13)/G13 -> 0.086254702 | J13: 0.083642 | K13: =(G13-J13)/G13 -> 0.10110693 | L13: llama1_13B
C14: 1 | D14: 511 | E14: 2560 | F14: 16 | G14: 0.071398 | H14: 0.066643 | I14: =(G14-H14)/G14 -> 0.066598504 | J14: 0.065542 | K14: =(G14-J14)/G14 -> 0.082019104 | L14: llama1_13B/baichuan1_13B(2卡)
C15: 1 | D15: 511 | E15: 2048 | F15: 16 | G15: 0.044826 | H15: 0.04007 | I15: =(G15-H15)/G15 -> 0.10609914 | J15: 0.040448 | K15: =(G15-J15)/G15 -> 0.097666533 | L15: llama2_70B(4卡)
C16: 1 | D16: 1024 | E16: 4096 | F16: 16 | G16: 0.15943 | H16: 0.148877 | I16: =(G16-H16)/G16 -> 0.066192059 | J16: 0.143718 | K16: =(G16-J16)/G16 -> 0.098551088 | L16: chatglm2 6B
... C57: 20 | D57: 512 | E57: 2048 | F57: 16 | G57: 0.541018 | H57: 0.463014 | I57: =(G57-H57)/G57 -> 0.14418005 | J57: 0.4568 | K57: =(G57-J57)/G57 -> 0.1556658 | L57: llama2_70B(4卡)

Sheet decoder理论计算
C6: DECODER | E6: Q: N*1*128 | G6: ldmma HBM带宽
E7: K: N*H*128 | G7: 38
E8: score: N*1*H
E9: V： N*H*128 | F9: N=1 cycle计算
F10: Q*K | K10: softmax | N10: score*vcache
D11: FP32 | E11: H | F11: a_size | G11: bbuf_size | H11: acycle | I11: b cycle | J11: mmacycle | K11: load mask | L11: scorefp32 ld/st | M11: score stm | N11: a_size | O11: bbuf_size | P11: acycle | Q11: b cycle | R11: mmacycle
E12: 128 | F12: =64*128*4 -> 32768 | G12: =E12*128*4 -> 65536 | H12: =F12/G7 -> 862.31579 | I12: =G12/G7 -> 1724.6316 | J12: =64*128*E12/(16384/2) -> 128 | K12: =L12/2 -> 215.57895 | L12: =2*4*16*E12/G7 -> 431.15789 | M12: =2*4*16*E12/G7 -> 431.15789 | N12: =64*E12*4 -> 32768 | O12: =E12*128*4 -> 65536 | P12: =N12/G7 -> 862.31579 | Q12: =O12/G7 -> 1724.6316 | R12: =64*E12*128/(16384/2) -> 128 | T12: =I12+K12+L12+M12+Q12 -> 4527.1579 | U12: =T12*2/1000 -> 9.0543158
E13: 256 | F13: =64*128*4 -> 32768 | G13: =E13*128*4 -> 131072 | H13: =F13/G7 -> 862.31579 | I13: =G13/G7 -> 3449.2632 | J13: =64*128*E13/(16384/2) -> 256 | K13: =L13/2 -> 431.15789 | L13: =2*4*16*E13/G7 -> 862.31579 | M13: =2*4*16*E13/G7 -> 862.31579 | N13: =64*E13*4 -> 65536 | O13: =E13*128*4 -> 131072 | P13: =N13/G7 -> 1724.6316 | Q13: =O13/G7 -> 3449.2632 | R13: =64*E13*128/(16384/2) -> 256 | T13: =I13+K13+L13+M13+Q13 -> 9054.3158 | U13: =T13*2/1000 -> 18.108632
E14: 512 | F14: =64*128*4 -> 32768 | G14: =E14*128*4 -> 262144 | H14: =F14/G7 -> 862.31579 | I14: =G14/G7 -> 6898.5263 | J14: =64*128*E14/(16384/2) -> 512 | K14: =L14/2 -> 862.31579 | L14: =2*4*16*E14/G7 -> 1724.6316 | M14: =2*4*16*E14/G7 -> 1724.6316 | N14: =64*E14*4 -> 131072 | O14: =E14*128*4 -> 262144 | P14: =N14/G7 -> 3449.2632 | Q14: =O14/G7 -> 6898.5263 | R14: =64*E14*128/(16384/2) -> 512 | T14: =I14+K14+L14+M14+Q14 -> 18108.632 | U14: =T14*2/1000 -> 36.217263
E15: 1024 | F15: =64*128*4 -> 32768 | G15: =E15*128*4 -> 524288 | H15: =F15/G7 -> 862.31579 | I15: =G15/G7 -> 13797.053 | J15: =64*128*E15/(16384/2) -> 1024 | K15: =L15/2 -> 1724.6316 | L15: =2*4*16*E15/G7 -> 3449.2632 | M15: =2*4*16*E15/G7 -> 3449.2632 | N15: =64*E15*4 -> 262144 | O15: =E15*128*4 -> 524288 | P15: =N15/G7 -> 6898.5263 | Q15: =O15/G7 -> 13797.053 | R15: =64*E15*128/(16384/2) -> 1024 | T15: =I15+K15+L15+M15+Q15 -> 36217.263 | U15: =T15*2/1000 -> 72.434526
D17: 单spcshape：Q[2,1,128],因为总的cycle较小，launch kernel的时间影响太大，测试的各部分cycle不具有参考性 | E17: N=1,head=32 for 16spc | F17: 理论 | G17: HBM实测 | H17: br利用率
E18: 128 | F18: 9.0543158 | G18: 46.016 | H18: =F18/G18 -> 0.19676451
E19: 256 | F19: 18.108632 | G19: 60.077 | H19: =F19/G19 -> 0.3014237
E20: 512 | F20: 36.217263 | G20: 80.538 | H20: =F20/G20 -> 0.44969161
E21: 1024 | F21: 72.434526 | G21: 114.47 | H21: =F21/G21 -> 0.63278174
G25: 总 | H25: reorder | I25: S*V | J25: softmax | K25: Q*K | L25: reorder | M25: S*V | N25: softmax | O25: Q*K
G26: 46.016 | H26: 20.198 | I26: 23.002 | J26: 20.16 | K26: 21.799 | L26: =H26/G26 -> 0.43893428 | M26: =I26/G26 -> 0.49986961 | N26: =J26/G26 -> 0.43810848 | O26: =K26/G26 -> 0.47372653
G27: 60.077 | H27: 20.422 | I27: 28.486 | J27: 22.515 | K27: 26.541 | L27: =H27/G27 -> 0.33993042 | M27: =I27/G27 -> 0.47415816 | N27: =J27/G27 -> 0.37476905 | O27: =K27/G27 -> 0.44178305
G28: 80.538 | H28: 20.666 | I28: 36.858 | J28: 24.627 | K28: 28.474 | L28: =H28/G28 -> 0.25659937 | M28: =I28/G28 -> 0.45764732 | N28: =J28/G28 -> 0.30578112 | O28: =K28/G28 -> 0.35354739
G29: 114.47 | H29: 20.525 | I29: 42.848 | J29: 29.645 | K29: 36.538 | L29: =H29/G29 -> 0.17930462 | M29: =I29/G29 -> 0.37431641 | N29: =J29/G29 -> 0.25897615 | O29: =K29/G29 -> 0.3191928
D31: 增大batch数，N=100, head=32（单spc[200,1,128]）理论性能以及测试结果：
H32: 理论性能 | I32: Q*K | J32: softmax | K32: S*V | L32: total
H33: H=128 | I33: =I12*100*2/1000 -> 344.92632 | J33: =(K12+L12+M12)*2*100/1000 -> 215.57895 | K33: =Q12*2*100/1000 -> 344.92632 | L33: =I33+J33+K33 -> 905.43158
H34: H=256 | I34: =I13*100*2/1000 -> 689.85263 | J34: =(K13+L13+M13)*2*100/1000 -> 431.15789 | K34: =Q13*2*100/1000 -> 689.85263 | L34: =I34+J34+K34 -> 1810.8632
H35: H=512 | I35: =I14*100*2/1000 -> 1379.7053 | J35: =(K14+L14+M14)*2*100/1000 -> 862.31579 | K35: =Q14*2*100/1000 -> 1379.7053 | L35: =I35+J35+K35 -> 3621.7263
H36: H=1024 | I36: =I15*100*2/1000 -> 2759.4105 | J36: =(K15+L15+M15)*2*100/1000 -> 1724.6316 | K36: =Q15*2*100/1000 -> 2759.4105 | L36: =I36+J36+K36 -> 7243.4526
F39: 实测性能性能 | G39: 总时间us | H39: reorder | I39: S*V | J39: softmax | K39: Q*K | L39: reorder | M39: S*V | N39: softmax | O39: Q*K
F40: H=128 | G40: 2168 | H40: 81.76 | I40: 1215 | J40: 483 | K40: 786 | L40: =H40/G40 -> 0.037712177 | M40: =I40/G40 -> 0.56042435 | N40: =J40/G40 -> 0.22278598 | O40: =K40/G40 -> 0.36254613 | P40: 各部分时间之和与总时间相差400~500cycle, 可以认为是提前load了一次vcache
F41: H=256 | G41: 2969 | H41: 82.21 | I41: 1525 | J41: 648 | K41: 1091 | L41: =H41/G41 -> 0.027689458 | M41: =I41/G41 -> 0.51364096 | N41: =J41/G41 -> 0.2182553 | O41: =K41/G41 -> 0.36746379
F42: H=512 | G42: 4743 | H42: 82.42 | I42: 2378 | J42: 856 | K42: 1919 | L42: =H42/G42 -> 0.017377187 | M42: =I42/G42 -> 0.50137044 | N42: =J42/G42 -> 0.18047649 | O42: =K42/G42 -> 0.40459625
F43: H=1024 | G43: 8058 | H43: 82.36 | I43: 3918 | J43: 1402 | K43: 3382 | L43: =H43/G43 -> 0.010220898 | M43: =I43/G43 -> 0.48622487 | N43: =J43/G43 -> 0.17398858 | O43: =K43/G43 -> 0.41970712
G45: 理论 | H45: HBM实测
F46: H=128 | G46: 905.43158 | H46: 2168 | I46: =G46/H46 -> 0.41763449
F47: H=256 | G47: 1810.8632 | H47: 2969 | I47: =G47/H47 -> 0.6099236
F48: H=512 | G48: 3621.7263 | H48: 4743 | I48: =G48/H48 -> 0.76359399
F49: H=1024 | G49: 7243.4526 | H49: 8058 | I49: =G49/H49 -> 0.89891445
H51: 将score_fp32配置为GMB时的性能
F52: H=128 | H52: 1906 | I52: =H52/H46 -> 0.87915129
F53: H=256 | H53: 2566 | I53: =H53/H47 -> 0.86426406
F54: H=512 | H54: 4292 | I54: =H54/H48 -> 0.9049125
...

Sheet encoder理论计算
C4: ENCODER
E5: Q: N*H*128
E6: K: N*H*128
E7: score: N*H*H
E8: V： N*H*128
F10: Q*K | K10: score*vcache
E11: H | F11: a_size | G11: bbuf_size | H11: acycle | I11: b cycle | J11: mmacycle | K11: a_size | L11: bbuf_size | M11: acycle | N11: b cycle | O11: mmacycle
E12: 128 | F12: =E12*128*4 -> 65536 | G12: =E12*128*4 -> 65536 | H12: =F12/decoder理论计算!G7 -> 1724.6316 | I12: =G12/decoder理论计算!G7 -> 1724.6316 | J12: =E12*128*E12/16384 -> 128 | K12: =E12*E12*4 -> 65536 | L12: =E12*128*4 -> 65536 | M12: =K12/decoder理论计算!G7 -> 1724.6316 | N12: =L12/decoder理论计算!G7 -> 1724.6316 | O12: =E12*E12*128/16384 -> 128
E13: 256 | F13: =E13*128*4 -> 131072 | G13: =E13*128*4 -> 131072 | H13: =F13/decoder理论计算!G7 -> 3449.2632 | I13: =G13/decoder理论计算!G7 -> 3449.2632 | J13: =E13*128*E13/16384 -> 512 | K13: =E13*E13*4 -> 262144 | L13: =E13*128*4 -> 131072 | M13: =K13/decoder理论计算!G7 -> 6898.5263 | N13: =L13/decoder理论计算!G7 -> 3449.2632 | O13: =E13*E13*128/16384 -> 512
E14: 512 | F14: =E14*128*4 -> 262144 | G14: =E14*128*4 -> 262144 | H14: =F14/decoder理论计算!G7 -> 6898.5263 | I14: =G14/7 -> 37449.143 | J14: =E14*128*E14/16384 -> 2048 | K14: =E14*E14*4 -> 1048576 | L14: =E14*128*4 -> 262144 | M14: =K14/decoder理论计算!G7 -> 27594.105 | N14: =L14/decoder理论计算!G7 -> 6898.5263 | O14: =E14*E14*128/16384 -> 2048
E15: 1024 | F15: =E15*128*4 -> 524288 | G15: =E15*128*4 -> 524288 | H15: =F15/decoder理论计算!G7 -> 13797.053 | I15: =G15/decoder理论计算!G7 -> 13797.053 | J15: =E15*128*E15/16384 -> 8192 | K15: =E15*E15*4 -> 4194304 | L15: =E15*128*4 -> 524288 | M15: =K15/decoder理论计算!G7 -> 110376.42 | N15: =L15/decoder理论计算!G7 -> 13797.053 | O15: =E15*E15*128/16384 -> 8192
